This location is identified as potentially faulty because it assumes that 'seq' is an iterable object that can be enumerated using the 'enumerate' function. If 'seq' is not iterable, this loop will throw an exception.